<?xml version="1.0" ?>
<robot name="partnet_c721d74df984ce23ac3de8d2d6e98e61">
	<link name="base"/>
	<link name="link_0">
		<visual name="outside_frame-1">
			<origin xyz="0 0 0"/>
			<geometry>
				<mesh filename="textured_objs/original-13.obj"/>
			</geometry>
		</visual>
		<collision>
			<origin xyz="0 0 0"/>
			<geometry>
				<mesh filename="textured_objs/original-13.obj"/>
			</geometry>
		</collision>
	</link>
	<joint name="joint_0" type="fixed">
		<origin rpy="1.570796326794897 0 -1.570796326794897" xyz="0 0 0"/>
		<child link="link_0"/>
		<parent link="base"/>
	</joint>
	<link name="link_1">
		<visual name="surface_board-10">
			<origin xyz="0.34140068467568707 -0.8378739999999993 -0.01673649490104201"/>
			<geometry>
				<mesh filename="textured_objs/original-12.obj"/>
			</geometry>
		</visual>
		<visual name="fixed_part-8">
			<origin xyz="0.34140068467568707 -0.8378739999999993 -0.01673649490104201"/>
			<geometry>
				<mesh filename="textured_objs/original-3.obj"/>
			</geometry>
		</visual>
		<visual name="fixed_part-6">
			<origin xyz="0.34140068467568707 -0.8378739999999993 -0.01673649490104201"/>
			<geometry>
				<mesh filename="textured_objs/original-8.obj"/>
			</geometry>
		</visual>
		<collision>
			<origin xyz="0.34140068467568707 -0.8378739999999993 -0.01673649490104201"/>
			<geometry>
				<mesh filename="textured_objs/original-12.obj"/>
			</geometry>
		</collision>
		<collision>
			<origin xyz="0.34140068467568707 -0.8378739999999993 -0.01673649490104201"/>
			<geometry>
				<mesh filename="textured_objs/original-3.obj"/>
			</geometry>
		</collision>
		<collision>
			<origin xyz="0.34140068467568707 -0.8378739999999993 -0.01673649490104201"/>
			<geometry>
				<mesh filename="textured_objs/original-8.obj"/>
			</geometry>
		</collision>
	</link>
	<joint name="joint_1" type="revolute">
		<origin xyz="-0.34140068467568707 0.8378739999999993 0.01673649490104201"/>
		<axis xyz="0 -1 0"/>
		<child link="link_1"/>
		<parent link="link_0"/>
		<limit lower="0.0" upper="1.5707963267948966"/>
	</joint>
	<link name="link_2">
		<visual name="movable_part-9">
			<origin xyz="-0.2881077343454585 0.09902238255745689 0.0026730000000000365"/>
			<geometry>
				<mesh filename="textured_objs/original-5.obj"/>
			</geometry>
		</visual>
		<visual name="movable_part-9">
			<origin xyz="-0.2881077343454585 0.09902238255745689 0.0026730000000000365"/>
			<geometry>
				<mesh filename="textured_objs/original-6.obj"/>
			</geometry>
		</visual>
		<visual name="movable_part-7">
			<origin xyz="-0.2881077343454585 0.09902238255745689 0.0026730000000000365"/>
			<geometry>
				<mesh filename="textured_objs/original-10.obj"/>
			</geometry>
		</visual>
		<visual name="movable_part-7">
			<origin xyz="-0.2881077343454585 0.09902238255745689 0.0026730000000000365"/>
			<geometry>
				<mesh filename="textured_objs/original-11.obj"/>
			</geometry>
		</visual>
		<collision>
			<origin xyz="-0.2881077343454585 0.09902238255745689 0.0026730000000000365"/>
			<geometry>
				<mesh filename="textured_objs/original-5.obj"/>
			</geometry>
		</collision>
		<collision>
			<origin xyz="-0.2881077343454585 0.09902238255745689 0.0026730000000000365"/>
			<geometry>
				<mesh filename="textured_objs/original-6.obj"/>
			</geometry>
		</collision>
		<collision>
			<origin xyz="-0.2881077343454585 0.09902238255745689 0.0026730000000000365"/>
			<geometry>
				<mesh filename="textured_objs/original-10.obj"/>
			</geometry>
		</collision>
		<collision>
			<origin xyz="-0.2881077343454585 0.09902238255745689 0.0026730000000000365"/>
			<geometry>
				<mesh filename="textured_objs/original-11.obj"/>
			</geometry>
		</collision>
	</link>
	<joint name="joint_2" type="fixed">
		<origin xyz="0.6295084190211455 -0.9368963825574562 -0.019409494901042046"/>
		<axis xyz="0 0 1"/>
		<child link="link_2"/>
		<parent link="link_1"/>
		<limit lower="-0.0" upper="1.5707963267948966"/>
	</joint>
</robot>
