<?xml version="1.0" ?>
<robot name="partnet_eb053a51aada526b2f332eb1bb219c10">
	<link name="base"/>
	<link name="link_0">
		<visual name="surface_board-9">
			<origin xyz="-0.2548381395579874 -0.7078869999999997 -0.1021876408472021"/>
			<geometry>
				<mesh filename="textured_objs/original-1.obj"/>
			</geometry>
		</visual>
		<visual name="surface_board-9">
			<origin xyz="-0.2548381395579874 -0.7078869999999997 -0.1021876408472021"/>
			<geometry>
				<mesh filename="textured_objs/original-3.obj"/>
			</geometry>
		</visual>
		<visual name="surface_board-9">
			<origin xyz="-0.2548381395579874 -0.7078869999999997 -0.1021876408472021"/>
			<geometry>
				<mesh filename="textured_objs/original-4.obj"/>
			</geometry>
		</visual>
		<visual name="surface_board-9">
			<origin xyz="-0.2548381395579874 -0.7078869999999997 -0.1021876408472021"/>
			<geometry>
				<mesh filename="textured_objs/original-8.obj"/>
			</geometry>
		</visual>
		<visual name="surface_board-9">
			<origin xyz="-0.2548381395579874 -0.7078869999999997 -0.1021876408472021"/>
			<geometry>
				<mesh filename="textured_objs/original-7.obj"/>
			</geometry>
		</visual>
		<visual name="surface_board-9">
			<origin xyz="-0.2548381395579874 -0.7078869999999997 -0.1021876408472021"/>
			<geometry>
				<mesh filename="textured_objs/original-10.obj"/>
			</geometry>
		</visual>
		<visual name="surface_board-9">
			<origin xyz="-0.2548381395579874 -0.7078869999999997 -0.1021876408472021"/>
			<geometry>
				<mesh filename="textured_objs/original-9.obj"/>
			</geometry>
		</visual>
		<visual name="surface_board-9">
			<origin xyz="-0.2548381395579874 -0.7078869999999997 -0.1021876408472021"/>
			<geometry>
				<mesh filename="textured_objs/original-11.obj"/>
			</geometry>
		</visual>
		<visual name="surface_board-9">
			<origin xyz="-0.2548381395579874 -0.7078869999999997 -0.1021876408472021"/>
			<geometry>
				<mesh filename="textured_objs/original-12.obj"/>
			</geometry>
		</visual>
		<visual name="surface_board-9">
			<origin xyz="-0.2548381395579874 -0.7078869999999997 -0.1021876408472021"/>
			<geometry>
				<mesh filename="textured_objs/original-13.obj"/>
			</geometry>
		</visual>
		<visual name="surface_board-9">
			<origin xyz="-0.2548381395579874 -0.7078869999999997 -0.1021876408472021"/>
			<geometry>
				<mesh filename="textured_objs/original-14.obj"/>
			</geometry>
		</visual>
		<visual name="fixed_part-10">
			<origin xyz="-0.2548381395579874 -0.7078869999999997 -0.1021876408472021"/>
			<geometry>
				<mesh filename="textured_objs/original-16.obj"/>
			</geometry>
		</visual>
		<visual name="fixed_part-10">
			<origin xyz="-0.2548381395579874 -0.7078869999999997 -0.1021876408472021"/>
			<geometry>
				<mesh filename="textured_objs/original-17.obj"/>
			</geometry>
		</visual>
		<collision>
			<origin xyz="-0.2548381395579874 -0.7078869999999997 -0.1021876408472021"/>
			<geometry>
				<mesh filename="textured_objs/original-1.obj"/>
			</geometry>
		</collision>
		<collision>
			<origin xyz="-0.2548381395579874 -0.7078869999999997 -0.1021876408472021"/>
			<geometry>
				<mesh filename="textured_objs/original-3.obj"/>
			</geometry>
		</collision>
		<collision>
			<origin xyz="-0.2548381395579874 -0.7078869999999997 -0.1021876408472021"/>
			<geometry>
				<mesh filename="textured_objs/original-4.obj"/>
			</geometry>
		</collision>
		<collision>
			<origin xyz="-0.2548381395579874 -0.7078869999999997 -0.1021876408472021"/>
			<geometry>
				<mesh filename="textured_objs/original-8.obj"/>
			</geometry>
		</collision>
		<collision>
			<origin xyz="-0.2548381395579874 -0.7078869999999997 -0.1021876408472021"/>
			<geometry>
				<mesh filename="textured_objs/original-7.obj"/>
			</geometry>
		</collision>
		<collision>
			<origin xyz="-0.2548381395579874 -0.7078869999999997 -0.1021876408472021"/>
			<geometry>
				<mesh filename="textured_objs/original-10.obj"/>
			</geometry>
		</collision>
		<collision>
			<origin xyz="-0.2548381395579874 -0.7078869999999997 -0.1021876408472021"/>
			<geometry>
				<mesh filename="textured_objs/original-9.obj"/>
			</geometry>
		</collision>
		<collision>
			<origin xyz="-0.2548381395579874 -0.7078869999999997 -0.1021876408472021"/>
			<geometry>
				<mesh filename="textured_objs/original-11.obj"/>
			</geometry>
		</collision>
		<collision>
			<origin xyz="-0.2548381395579874 -0.7078869999999997 -0.1021876408472021"/>
			<geometry>
				<mesh filename="textured_objs/original-12.obj"/>
			</geometry>
		</collision>
		<collision>
			<origin xyz="-0.2548381395579874 -0.7078869999999997 -0.1021876408472021"/>
			<geometry>
				<mesh filename="textured_objs/original-13.obj"/>
			</geometry>
		</collision>
		<collision>
			<origin xyz="-0.2548381395579874 -0.7078869999999997 -0.1021876408472021"/>
			<geometry>
				<mesh filename="textured_objs/original-14.obj"/>
			</geometry>
		</collision>
		<collision>
			<origin xyz="-0.2548381395579874 -0.7078869999999997 -0.1021876408472021"/>
			<geometry>
				<mesh filename="textured_objs/original-16.obj"/>
			</geometry>
		</collision>
		<collision>
			<origin xyz="-0.2548381395579874 -0.7078869999999997 -0.1021876408472021"/>
			<geometry>
				<mesh filename="textured_objs/original-17.obj"/>
			</geometry>
		</collision>
	</link>
	<joint name="joint_0" type="revolute">
		<origin xyz="0.2548381395579874 0.7078869999999997 0.1021876408472021"/>
		<axis xyz="0 -1 0"/>
		<child link="link_0"/>
		<parent link="link_1"/>
		<limit lower="-0.8726646259971648" upper="0.6981317007977318"/>
	</joint>
	<link name="link_1">
		<visual name="outside_frame-6">
			<origin xyz="0 0 0"/>
			<geometry>
				<mesh filename="textured_objs/original-5.obj"/>
			</geometry>
		</visual>
		<visual name="outside_frame-6">
			<origin xyz="0 0 0"/>
			<geometry>
				<mesh filename="textured_objs/original-6.obj"/>
			</geometry>
		</visual>
		<visual name="outside_frame-6">
			<origin xyz="0 0 0"/>
			<geometry>
				<mesh filename="textured_objs/new-1.obj"/>
			</geometry>
		</visual>
		<visual name="other_leaf-8">
			<origin xyz="0 0 0"/>
			<geometry>
				<mesh filename="textured_objs/new-0.obj"/>
			</geometry>
		</visual>
		<collision>
			<origin xyz="0 0 0"/>
			<geometry>
				<mesh filename="textured_objs/original-5.obj"/>
			</geometry>
		</collision>
		<collision>
			<origin xyz="0 0 0"/>
			<geometry>
				<mesh filename="textured_objs/original-6.obj"/>
			</geometry>
		</collision>
		<collision>
			<origin xyz="0 0 0"/>
			<geometry>
				<mesh filename="textured_objs/new-1.obj"/>
			</geometry>
		</collision>
		<collision>
			<origin xyz="0 0 0"/>
			<geometry>
				<mesh filename="textured_objs/new-0.obj"/>
			</geometry>
		</collision>
	</link>
	<joint name="joint_1" type="fixed">
		<origin rpy="1.570796326794897 0 -1.570796326794897" xyz="0 0 0"/>
		<child link="link_1"/>
		<parent link="base"/>
	</joint>
</robot>
